Workbook

Sheet Summary
A1: South Africa payroll localisation - 12-month reconciliation
A2: Metric Engineering (Pty) Ltd | 11 fictitious employees | Oct 2025 - Sep 2026 | Prepared 7 October 2026
A4: Measure | B4: Source | C4: System | D4: Difference
A5: 12-month PAYE (R) | B5: ='PAYE by Employee'!N16 -> 3478128.4 | C5: ='PAYE by Employee'!N31 -> 3478043.4 | D5: =C5-B5 -> -84.96
A6: 12-month total earnings (R) | B6: ='Monthly Company Totals'!B17 -> 11730358 | C6: ='Monthly Company Totals'!C17 -> 11730358 | D6: =C6-B6 -> 0
A7: 12-month UIF employee (R) | B7: ='Monthly Company Totals'!H17 -> 23379.84 | C7: ='Monthly Company Totals'!I17 -> 23379.84 | D7: =C7-B7 -> 0
A8: 12-month SDL (R) | B8: ='Monthly Company Totals'!N17 -> 115752.8 | C8: ='Monthly Company Totals'!O17 -> 115752.79 | D8: =C8-B8 -> -0.01
A9: 12-month company contributions (R) | B9: ='Monthly Company Totals'!Q17 -> 139132.64 | C9: ='Monthly Company Totals'!R17 -> 139132.63 | D9: =C9-B9 -> -0.01
A11: Key findings
A12: Result: earnings, UIF, SDL and company contributions match exactly (SDL differs by R0.01 in total).
A13: PAYE matches within R0.05 in 93 of 132 employee-months and within R0.40 in 14 more. The remaining 25 cells fall into two causes: source applied 2025/26 tables in March 2026 and corrected in April (22 cells, nets to cents), and employee 003 retirement-annuity treatment (3 cells).
A14: 12-month PAYE: system is R84.96 below the source; R84.77 of that is employee 003 (Aug 2026).
A15: No overrides or manual amounts: all figures come from Salary Structure, Additional Salary, SSA, take-on and the SA payroll engine.
A16: Opening balances for Mar-Sep 2025 are derived, not supplied. Treat Oct 2025 as calibration and Nov 2025 onwards as the test.
A17: Recommendation: CONDITIONAL GO - see RECONCILIATION_REPORT.md for conditions and confidence by domain.

Sheet PAYE by Employee
A1: PAYE by employee and month: source vs system
A2: Source = GS Test Employee12MonthReport.xlsx. System = Salary Slips calculated on cohenix.localhost (Metric Engineering (Pty) Ltd). Difference = System - Source (formula).
A3: Source (GS report)
A4: Employee | B4: Oct 2025 | C4: Nov 2025 | D4: Dec 2025 | E4: Jan 2026 | F4: Feb 2026 | G4: Mar 2026 | H4: Apr 2026 | I4: May 2026 | J4: Jun 2026 | K4: Jul 2026 | L4: Aug 2026 | M4: Sep 2026 | N4: 12-month total
A5: Thabo Mokoena - 001 | B5: 28378.53 | C5: 28593.14 | D5: 27448.48 | E5: 24586.86 | F5: 28020.56 | G5: 27374.69 | H5: 27854.18 | I5: 27042.11 | J5: 27614.43 | K5: 27757.52 | L5: 28186.76 | M5: 27614.43 | N5: =SUM(B5:M5) -> 330471.69
A6: Lerato Dlamini - 002 | B6: 69854.87 | C6: 75336.41 | D6: 63002.95 | E6: 43817.57 | F6: 33539.44 | G6: 36165.17 | H6: 45221.52 | I6: 49797.1 | J6: 78493.18 | K6: 49269.45 | L6: 81975.97 | M6: 76815.03 | N6: =SUM(B6:M6) -> 703288.66
A7: Pieter van der Merwe - 003 | B7: 8006.3 | C7: 8880.18 | D7: 9021.55 | E7: 7009.85 | F7: 8049.47 | G7: 8093.54 | H7: 8586.56 | I7: 8741.12 | J7: 5923.62 | K7: 6671.73 | L7: 9591.95 | M7: 6474.32 | N7: =SUM(B7:M7) -> 95050.19
A8: Naledi Khumalo - 004 | B8: 59738.55 | C8: 59738.55 | D8: 59738.54 | E8: 59738.55 | F8: 59738.13 | G8: 62047.95 | H8: 76722.11 | I8: 61510.04 | J8: 61510.03 | K8: 61514.42 | L8: 61514.42 | M8: 77264.42 | N8: =SUM(B8:M8) -> 760775.71
A9: Sipho Ndlovu - 005 | B9: 13592.7 | C9: 15321.88 | D9: 14355.06 | E9: 13724.64 | F9: 15232.48 | G9: 13768.75 | H9: 10659.32 | I9: 12210.61 | J9: 14177.12 | K9: 16571.64 | L9: 15799.52 | M9: 14412.11 | N9: =SUM(B9:M9) -> 169825.83
A10: Annelie Botha - 006 | B10: 55876.43 | C10: 55795.44 | D10: 55548.29 | E10: 28893.9 | F10: 14407.28 | G10: 58893.14 | H10: 14073.14 | I10: 15744.31 | J10: 27972.46 | K10: 15038.71 | L10: 15038.7 | M10: 25883.92 | N10: =SUM(B10:M10) -> 383165.72
A11: Kagiso Molefe - 007 | B11: 9697.2 | C11: 9697.2 | D11: 9697.2 | E11: 9697.21 | F11: 9697.02 | G11: 12782.4 | H11: 12328.23 | I11: 12555.32 | J11: 12555.32 | K11: 12561.1 | L11: 12561.09 | M11: 12561.1 | N11: =SUM(B11:M11) -> 136390.39
A12: Ayesha Patel - 008 | B12: 9604.72 | C12: 9775.02 | D12: 9264.15 | E12: 10320.08 | F12: 10079.34 | G12: 8644.16 | H12: 7749.93 | I12: 10387.75 | J12: 9594.49 | K12: 7654.17 | L12: 10068.59 | M12: 8237.68 | N12: =SUM(B12:M12) -> 111380.08
A13: Johan Pretorius - 009 | B13: 20302.54 | C13: 19507.27 | D13: 19756.54 | E13: 18569.57 | F13: 18664.31 | G13: 20952.9 | H13: 19746.79 | I13: 18203.47 | J13: 19985.49 | K13: 20207.16 | L13: 20648.13 | M13: 20305.15 | N13: =SUM(B13:M13) -> 236849.32
A14: Zanele Nkosi - 010 | B14: 9588.23 | C14: 9588.23 | D14: 9588.24 | E14: 9588.23 | F14: 9588.06 | G14: 12502.8 | H14: 12048.62 | I14: 12275.72 | J14: 15378.91 | K14: 15386.12 | L14: 15386.12 | M14: 15445.92 | N14: =SUM(B14:M14) -> 146365.2
A15: Michael O'Connor - 011 | B15: 30371.76 | C15: 27119.72 | D15: 25434.73 | E15: 31382.76 | F15: 28366.36 | G15: 34783.42 | H15: 37962.66 | I15: 42036.12 | J15: 35914.67 | K15: 38781.07 | L15: 39558.39 | M15: 32853.95 | N15: =SUM(B15:M15) -> 404565.61
A16: Company total | B16: =SUM(B5:B15) -> 315011.83 | C16: =SUM(C5:C15) -> 319353.04 | D16: =SUM(D5:D15) -> 302855.73 | E16: =SUM(E5:E15) -> 257329.22 | F16: =SUM(F5:F15) -> 235382.45 | G16: =SUM(G5:G15) -> 296008.92 | H16: =SUM(H5:H15) -> 272953.06 | I16: =SUM(I5:I15) -> 270503.67 | ... N16: =SUM(N5:N15) -> 3478128.4
A18: System (za_local_payroll)
A19: Employee | B19: Oct 2025 | C19: Nov 2025 | D19: Dec 2025 | E19: Jan 2026 | F19: Feb 2026 | G19: Mar 2026 | H19: Apr 2026 | I19: May 2026 | J19: Jun 2026 | K19: Jul 2026 | L19: Aug 2026 | M19: Sep 2026 | N19: 12-month total
A20: Thabo Mokoena - 001 | B20: 28378.53 | C20: 28593.13 | D20: 27448.46 | E20: 24586.84 | F20: 28020.79 | G20: 27042.08 | H20: 28186.74 | I20: 27042.09 | J20: 27614.41 | K20: 27757.5 | L20: 28186.73 | M20: 27614.42 | N20: =SUM(B20:M20) -> 330471.72
A21: Lerato Dlamini - 002 | B21: 69854.87 | C21: 75336.39 | D21: 63002.97 | E21: 43817.51 | F21: 33539.68 | G21: 35832.57 | H21: 45554.07 | I21: 49797.09 | J21: 78493.15 | K21: 49269.43 | L21: 81975.94 | M21: 76814.86 | N21: =SUM(B21:M21) -> 703288.53
A22: Pieter van der Merwe - 003 | B22: 8006.3 | C22: 8880.18 | D22: 9021.54 | E22: 6936.47 | F22: 8122.88 | G22: 7938.95 | H22: 8741.12 | I22: 8741.13 | J22: 5923.61 | K22: 6671.73 | L22: 9507.18 | M22: 6474.32 | N22: =SUM(B22:M22) -> 94965.41
A23: Naledi Khumalo - 004 | B23: 59738.55 | C23: 59738.51 | D23: 59738.52 | E23: 59738.51 | F23: 59738.51 | G23: 61510 | H23: 77259.99 | I23: 61510 | J23: 61510 | K23: 61514.38 | L23: 61514.38 | M23: 77264.39 | N23: =SUM(B23:M23) -> 760775.74
A24: Sipho Ndlovu - 005 | B24: 13592.7 | C24: 15321.85 | D24: 14355.05 | E24: 13724.62 | F24: 15232.67 | G24: 13520.42 | H24: 10907.62 | I24: 12210.59 | J24: 14177.11 | K24: 16571.63 | L24: 15799.5 | M24: 14412.09 | N24: =SUM(B24:M24) -> 169825.85
A25: Annelie Botha - 006 | B25: 55876.43 | C25: 55795.4 | D25: 55548.26 | E25: 28893.86 | F25: 14407.38 | G25: 58343.19 | H25: 14623.04 | I25: 15744.3 | J25: 27972.43 | K25: 15038.69 | L25: 15038.68 | M25: 25883.9 | N25: =SUM(B25:M25) -> 383165.56
A26: Kagiso Molefe - 007 | B26: 9697.2 | C26: 9697.19 | D26: 9697.18 | E26: 9697.19 | F26: 9697.18 | G26: 12555.3 | H26: 12555.3 | I26: 12555.31 | J26: 12555.3 | K26: 12561.08 | L26: 12561.09 | M26: 12561.08 | N26: =SUM(B26:M26) -> 136390.4
A27: Ayesha Patel - 008 | B27: 9604.72 | C27: 9775 | D27: 9264.15 | E27: 10320.02 | F27: 10079.5 | G27: 8489.56 | H27: 7904.51 | I27: 10387.73 | J27: 9594.47 | K27: 7654.18 | L27: 10068.54 | M27: 8237.71 | N27: =SUM(B27:M27) -> 111380.09
A28: Johan Pretorius - 009 | B28: 20302.54 | C28: 19507.26 | D28: 19756.57 | E28: 18569.5 | F28: 18664.51 | G28: 20620.29 | H28: 20079.36 | I28: 18203.45 | J28: 19985.47 | K28: 20207.15 | L28: 20648.1 | M28: 20305.14 | N28: =SUM(B28:M28) -> 236849.34
A29: Zanele Nkosi - 010 | B29: 9588.23 | C29: 9588.22 | D29: 9588.22 | E29: 9588.22 | F29: 9588.22 | G29: 12275.7 | H29: 12275.69 | I29: 12275.7 | J29: 15378.9 | K29: 15386.1 | L29: 15386.11 | M29: 15445.87 | N29: =SUM(B29:M29) -> 146365.18
A30: Michael O'Connor - 011 | B30: 30371.76 | C30: 27119.69 | D30: 25434.7 | E30: 31382.75 | F30: 28366.59 | G30: 34450.82 | H30: 38295.21 | I30: 42036.1 | J30: 35914.65 | K30: 38781.05 | L30: 39558.37 | M30: 32853.93 | N30: =SUM(B30:M30) -> 404565.62
A31: Company total | B31: =SUM(B20:B30) -> 315011.83 | C31: =SUM(C20:C30) -> 319352.82 | D31: =SUM(D20:D30) -> 302855.62 | E31: =SUM(E20:E30) -> 257255.49 | F31: =SUM(F20:F30) -> 235457.91 | G31: =SUM(G20:G30) -> 292578.88 | H31: =SUM(H20:H30) -> 276382.65 | I31: =SUM(I20:I30) -> 270503.49 | ... N31: =SUM(N20:N30) -> 3478043.4
A33: Difference (System - Source)
A34: Employee | B34: Oct 2025 | C34: Nov 2025 | D34: Dec 2025 | E34: Jan 2026 | F34: Feb 2026 | G34: Mar 2026 | H34: Apr 2026 | I34: May 2026 | J34: Jun 2026 | K34: Jul 2026 | L34: Aug 2026 | M34: Sep 2026 | N34: 12-month total
A35: Thabo Mokoena - 001 | B35: =B20-B5 -> 0 | C35: =C20-C5 -> -0.01 | D35: =D20-D5 -> -0.02 | E35: =E20-E5 -> -0.02 | F35: =F20-F5 -> 0.23 | G35: =G20-G5 -> -332.61 | H35: =H20-H5 -> 332.56 | I35: =I20-I5 -> -0.02 | ... M35: =M20-M5 -> -0.01 | N35: =SUM(B35:M35) -> 0.03
A36: Lerato Dlamini - 002 | B36: =B21-B6 -> 0 | C36: =C21-C6 -> -0.02 | D36: =D21-D6 -> 0.02 | E36: =E21-E6 -> -0.06 | F36: =F21-F6 -> 0.24 | G36: =G21-G6 -> -332.6 | H36: =H21-H6 -> 332.55 | I36: =I21-I6 -> -0.01 | ... M36: =M21-M6 -> -0.17 | N36: =SUM(B36:M36) -> -0.13
A37: Pieter van der Merwe - 003 | B37: =B22-B7 -> 0 | C37: =C22-C7 -> 0 | D37: =D22-D7 -> -0.01 | E37: =E22-E7 -> -73.38 | F37: =F22-F7 -> 73.41 | G37: =G22-G7 -> -154.59 | H37: =H22-H7 -> 154.56 | I37: =I22-I7 -> 0.01 | ... M37: =M22-M7 -> 0 | N37: =SUM(B37:M37) -> -84.78
A38: Naledi Khumalo - 004 | B38: =B23-B8 -> 0 | C38: =C23-C8 -> -0.04 | D38: =D23-D8 -> -0.02 | E38: =E23-E8 -> -0.04 | F38: =F23-F8 -> 0.38 | G38: =G23-G8 -> -537.95 | H38: =H23-H8 -> 537.88 | I38: =I23-I8 -> -0.04 | ... M38: =M23-M8 -> -0.03 | N38: =SUM(B38:M38) -> 0.03
A39: Sipho Ndlovu - 005 | B39: =B24-B9 -> 0 | C39: =C24-C9 -> -0.03 | D39: =D24-D9 -> -0.01 | E39: =E24-E9 -> -0.02 | F39: =F24-F9 -> 0.19 | G39: =G24-G9 -> -248.33 | H39: =H24-H9 -> 248.3 | I39: =I24-I9 -> -0.02 | ... M39: =M24-M9 -> -0.02 | N39: =SUM(B39:M39) -> 0.02
A40: Annelie Botha - 006 | B40: =B25-B10 -> 0 | C40: =C25-C10 -> -0.04 | D40: =D25-D10 -> -0.03 | E40: =E25-E10 -> -0.04 | F40: =F25-F10 -> 0.1 | G40: =G25-G10 -> -549.95 | H40: =H25-H10 -> 549.9 | I40: =I25-I10 -> -0.01 | ... M40: =M25-M10 -> -0.02 | N40: =SUM(B40:M40) -> -0.16
A41: Kagiso Molefe - 007 | B41: =B26-B11 -> 0 | C41: =C26-C11 -> -0.01 | D41: =D26-D11 -> -0.02 | E41: =E26-E11 -> -0.02 | F41: =F26-F11 -> 0.16 | G41: =G26-G11 -> -227.1 | H41: =H26-H11 -> 227.07 | I41: =I26-I11 -> -0.01 | ... M41: =M26-M11 -> -0.02 | N41: =SUM(B41:M41) -> 0.01
A42: Ayesha Patel - 008 | B42: =B27-B12 -> 0 | C42: =C27-C12 -> -0.02 | D42: =D27-D12 -> 0 | E42: =E27-E12 -> -0.06 | F42: =F27-F12 -> 0.16 | G42: =G27-G12 -> -154.6 | H42: =H27-H12 -> 154.58 | I42: =I27-I12 -> -0.02 | ... M42: =M27-M12 -> 0.03 | N42: =SUM(B42:M42) -> 0.01
...

Sheet Monthly Company Totals
A1: Company totals per month (11 employees)
A2: Blue = values from data; black = formulas. Differences are System - Source.
A4: Month | B4: Total earnings (TOT:EARN) - Source | C4: Total earnings (TOT:EARN) - System | D4: Total earnings (TOT:EARN) - Diff | E4: PAYE - Source | F4: PAYE - System | G4: PAYE - Diff | H4: UIF employee - Source | I4: UIF employee - System | J4: UIF employee - Diff | K4: UIF employer - Source | L4: UIF employer - System | M4: UIF employer - Diff | N4: SDL - Source | O4: SDL - System | P4: SDL - Diff | Q4: Total company contributions (TOT:CC) - Source | R4: Total company contributions (TOT:CC) - System | S4: Total company contributions (TOT:CC) - Diff | T4: Total deductions (TOT:DED) - Source | U4: Total deductions (TOT:DED) - System | V4: Total deductions (TOT:DED) - Diff
A5: Oct 2025 | B5: 1034472.6 | C5: 1034472.6 | D5: =C5-B5 -> 0 | E5: 315011.83 | F5: 315011.83 | G5: =F5-E5 -> 0 | H5: 1948.32 | I5: 1948.32 | J5: =I5-H5 -> 0 | K5: 1948.32 | L5: 1948.32 | M5: =L5-K5 -> 0 | N5: 10206.15 | O5: 10206.14 | P5: =O5-N5 -> -0.01 | Q5: 12154.47 | R5: 12154.46 | S5: =R5-Q5 -> -0.01 | T5: 320800.34 | U5: 327881.25 | V5: =U5-T5 -> 7080.91
A6: Nov 2025 | B6: 1043661.5 | C6: 1043661.5 | D6: =C6-B6 -> 0 | E6: 319353.04 | F6: 319352.82 | G6: =F6-E6 -> -0.22 | H6: 1948.32 | I6: 1948.32 | J6: =I6-H6 -> 0 | K6: 1948.32 | L6: 1948.32 | M6: =L6-K6 -> 0 | N6: 10320.74 | O6: 10320.74 | P6: =O6-N6 -> 0 | Q6: 12269.06 | R6: 12269.06 | S6: =R6-Q6 -> 0 | T6: 325141.55 | U6: 332491.33 | V6: =U6-T6 -> 7349.78
A7: Dec 2025 | B7: 1001831.6 | C7: 1001831.6 | D7: =C7-B7 -> 0 | E7: 302855.73 | F7: 302855.62 | G7: =F7-E7 -> -0.11 | H7: 1948.32 | I7: 1948.32 | J7: =I7-H7 -> 0 | K7: 1948.32 | L7: 1948.32 | M7: =L7-K7 -> 0 | N7: 9914.24 | O7: 9914.24 | P7: =O7-N7 -> 0 | Q7: 11862.56 | R7: 11862.56 | S7: =R7-Q7 -> 0 | T7: 308644.24 | U7: 315994.13 | V7: =U7-T7 -> 7349.89
A8: Jan 2026 | B8: 896720.73 | C8: 896720.73 | D8: =C8-B8 -> 0 | E8: 257329.22 | F8: 257255.49 | G8: =F8-E8 -> -73.73 | H8: 1948.32 | I8: 1948.32 | J8: =I8-H8 -> 0 | K8: 1948.32 | L8: 1948.32 | M8: =L8-K8 -> 0 | N8: 8846.24 | O8: 8846.24 | P8: =O8-N8 -> 0 | Q8: 10794.56 | R8: 10794.56 | S8: =R8-Q8 -> 0 | T8: 263117.73 | U8: 270394 | V8: =U8-T8 -> 7276.27
A9: Feb 2026 | B9: 841914.37 | C9: 841914.37 | D9: =C9-B9 -> 0 | E9: 235382.45 | F9: 235457.91 | G9: =F9-E9 -> 75.46 | H9: 1948.32 | I9: 1948.32 | J9: =I9-H9 -> 0 | K9: 1948.32 | L9: 1948.32 | M9: =L9-K9 -> 0 | N9: 8277.61 | O9: 8277.61 | P9: =O9-N9 -> 0 | Q9: 10225.93 | R9: 10225.93 | S9: =R9-Q9 -> 0 | T9: 241170.96 | U9: 248596.42 | V9: =U9-T9 -> 7425.46
A10: Mar 2026 | B10: 988356.71 | C10: 988356.71 | D10: =C10-B10 -> 0 | E10: 296008.92 | F10: 292578.88 | G10: =F10-E10 -> -3430.04 | H10: 1948.32 | I10: 1948.32 | J10: =I10-H10 -> 0 | K10: 1948.32 | L10: 1948.32 | M10: =L10-K10 -> 0 | N10: 9743.58 | O10: 9743.58 | P10: =O10-N10 -> 0 | Q10: 11691.9 | R10: 11691.9 | S10: =R10-Q10 -> 0 | T10: 301797.43 | U10: 305717.39 | V10: =U10-T10 -> 3919.96
A11: Apr 2026 | B11: 946171.17 | C11: 946171.17 | D11: =C11-B11 -> 0 | E11: 272953.06 | F11: 276382.65 | G11: =F11-E11 -> 3429.59 | H11: 1948.32 | I11: 1948.32 | J11: =I11-H11 -> 0 | K11: 1948.32 | L11: 1948.32 | M11: =L11-K11 -> 0 | N11: 9327.52 | O11: 9327.52 | P11: =O11-N11 -> 0 | Q11: 11275.84 | R11: 11275.84 | S11: =R11-Q11 -> 0 | T11: 278741.57 | U11: 289521.16 | V11: =U11-T11 -> 10779.59
A12: May 2026 | B12: 934560.42 | C12: 934560.42 | D12: =C12-B12 -> 0 | E12: 270503.67 | F12: 270503.49 | G12: =F12-E12 -> -0.18 | H12: 1948.32 | I12: 1948.32 | J12: =I12-H12 -> 0 | K12: 1948.32 | L12: 1948.32 | M12: =L12-K12 -> 0 | N12: 9230.11 | O12: 9230.11 | P12: =O12-N12 -> 0 | Q12: 11178.43 | R12: 11178.43 | S12: =R12-Q12 -> 0 | T12: 276292.18 | U12: 283642 | V12: =U12-T12 -> 7349.82
A13: Jun 2026 | B13: 1031501.7 | C13: 1031501.7 | D13: =C13-B13 -> 0 | E13: 309119.72 | F13: 309119.5 | G13: =F13-E13 -> -0.22 | H13: 1948.32 | I13: 1948.32 | J13: =I13-H13 -> 0 | K13: 1948.32 | L13: 1948.32 | M13: =L13-K13 -> 0 | N13: 10160.47 | O13: 10160.47 | P13: =O13-N13 -> 0 | Q13: 12108.79 | R13: 12108.79 | S13: =R13-Q13 -> 0 | T13: 370958.23 | U13: 378308.01 | V13: =U13-T13 -> 7349.78
A14: Jul 2026 | B14: 936029.24 | C14: 936029.24 | D14: =C14-B14 -> 0 | E14: 271413.09 | F14: 271412.92 | G14: =F14-E14 -> -0.17 | H14: 1948.32 | I14: 1948.32 | J14: =I14-H14 -> 0 | K14: 1948.32 | L14: 1948.32 | M14: =L14-K14 -> 0 | N14: 9243.87 | O14: 9243.87 | P14: =O14-N14 -> 0 | Q14: 11192.19 | R14: 11192.19 | S14: =R14-Q14 -> 0 | T14: 277378.9 | U14: 284985.98 | V14: =U14-T14 -> 7607.08
A15: Aug 2026 | B15: 1036225.5 | C15: 1036225.5 | D15: =C15-B15 -> 0 | E15: 310329.64 | F15: 310244.62 | G15: =F15-E15 -> -85.02 | H15: 1948.32 | I15: 1948.32 | J15: =I15-H15 -> 0 | K15: 1948.32 | L15: 1948.32 | M15: =L15-K15 -> 0 | N15: 10227.28 | O15: 10227.28 | P15: =O15-N15 -> 0 | Q15: 12175.6 | R15: 12175.6 | S15: =R15-Q15 -> 0 | T15: 316294.34 | U15: 323816.57 | V15: =U15-T15 -> 7522.23
A16: Sep 2026 | B16: 1038912.3 | C16: 1038912.3 | D16: =C16-B16 -> 0 | E16: 317868.03 | F16: 317867.71 | G16: =F16-E16 -> -0.32 | H16: 1948.32 | I16: 1948.32 | J16: =I16-H16 -> 0 | K16: 1948.32 | L16: 1948.32 | M16: =L16-K16 -> 0 | N16: 10254.99 | O16: 10254.99 | P16: =O16-N16 -> 0 | Q16: 12203.31 | R16: 12203.31 | S16: =R16-Q16 -> 0 | T16: 323832.73 | U16: 331439.66 | V16: =U16-T16 -> 7606.93
A17: 12-month total | B17: =SUM(B5:B16) -> 11730358 | C17: =SUM(C5:C16) -> 11730358 | D17: =SUM(D5:D16) -> 0 | E17: =SUM(E5:E16) -> 3478128.4 | F17: =SUM(F5:F16) -> 3478043.4 | G17: =SUM(G5:G16) -> -84.96 | H17: =SUM(H5:H16) -> 23379.84 | I17: =SUM(I5:I16) -> 23379.84 | ... V17: =SUM(V5:V16) -> 88617.7
A19: Note: TOT:DED differs only for employee 003 (RAF 7 080.91-7 607.25 per month). The source shows RAF as a memo line outside TOT:DED; the system deducts it like any retirement-annuity contribution so the GL (Payroll Payable) stays consistent with net pay.

Sheet Line Item Reconciliation
A1: Line-by-line reconciliation (132 employee-months)
A2: Every source line compared with the corresponding Salary Slip row. 'Within 1c' counts cells where |difference| <= R0.01.
A4: Source line | B4: Cells compared | C4: Within 1c | D4: Largest |difference| | E4: Source total | F4: System total | G4: Total difference
A5: TOT:EARN | B5: 132 | C5: 132 | D5: 0 | E5: 11730358 | F5: 11730358 | G5: =F5-E5 -> 0
A6: PAYE | B6: 132 | C6: 37 | D6: 549.95 | E6: 3478128.4 | F6: 3478043.4 | G6: =F6-E6 -> -84.96
A7: UIF (employee) | B7: 132 | C7: 132 | D7: 0 | E7: 23379.84 | F7: 23379.84 | G7: =F7-E7 -> 0
A8: TOT:DED | B8: 132 | C8: 30 | D8: 7607.25 | E8: 3604170.2 | F8: 3692787.9 | G8: =F8-E8 -> 88617.7
A9: SDL | B9: 132 | C9: 132 | D9: 0.01 | E9: 115752.8 | F9: 115752.79 | G9: =F9-E9 -> -0.01
A10: UIF (employer) | B10: 132 | C10: 132 | D10: 0 | E10: 23379.84 | F10: 23379.84 | G10: =F10-E10 -> 0
A11: TOT:CC | B11: 132 | C11: 132 | D11: 0.01 | E11: 139132.64 | F11: 139132.63 | G11: =F11-E11 -> -0.01
A12: line:SALARY | B12: 132 | C12: 132 | D12: 0 | E12: 7477489 | F12: 7477489 | G12: =F12-E12 -> 0
A13: line:LAPTOP_ALLOW | B13: 108 | C13: 108 | D13: 0 | E13: 165240 | F13: 165240 | G13: =F13-E13 -> 0
A14: line:LIFE_COVER | B14: 132 | C14: 132 | D14: 0 | E14: 21319.14 | F14: 21319.14 | G14: =F14-E14 -> 0
A15: line:COMM_REIMBURSE | B15: 48 | C15: 48 | D15: 0 | E15: 47772.26 | F15: 47772.26 | G15: =F15-E15 -> 0
A16: line:HBR | B16: 72 | C16: 72 | D16: 0 | E16: 1308244.9 | F16: 1308244.9 | G16: =F16-E16 -> 0
... A26: line:EXPCLAIM | B26: 48 | C26: 48 | D26: 0 | E26: 18608.25 | F26: 18608.25 | G26: =F26-E26 -> 0

Sheet PAYE Variance Analysis
A1: Where PAYE differs and why
A2: 132 PAYE cells (11 employees x 12 months).
A4: Category | B4: Cells | C4: Explanation
A5: Within R0.05 | B5: 93 | C5: Matches the source to the cent, or within cumulative rounding.
A6: R0.06 - R0.40 (rounding) | B6: 14 | C6: February (year-end) cumulative rounding, plus a few cells at R0.06-R0.07. Largest R0.38.
A7: March / April 2026 (all 11) | B7: 22 | C7: Source taxed March 2026 on the 2025/26 tables and corrected in April. System applies the 2026/27 tables from 1 March 2026. Mar + Apr combined differ by R0.02-R0.07 per employee.
A8: Employee 003 - Jan, Feb, Aug | B8: 3 | C8: -R73.38 / +R73.41 (Jan/Feb, reverses) and -R84.77 (Aug, persists). Source retirement-annuity deduction behaves differently from the RAF memo amount in those months; unexplained.
A9: Total | B9: =SUM(B5:B8) -> 132

Sheet Configuration Register
A1: What was configured on cohenix.localhost
A2: Company: Metric Engineering (Pty) Ltd (MET). Payroll apps: za_local_core 2.0.0, za_local_payroll 2.1.0, za_local_bma 0.1.0 on Frappe/ERPNext 16.50.0, HRMS 16.20.1.
A4: Salary component | B4: Type | C4: Source code | D4: SARS code | E4: Treatment | F4: PAYE % | G4: UIF | H4: SDL | I4: COIDA | J4: Notes
A5: SALARY | B5: Earning | C5: SALARY | D5: 3601 | E5: Regular Remuneration | F5: 100 | G5: 1 | H5: 1 | I5: 1 | J5: Structure formula = base; ETI wage component
A6: LAPTOP_ALLOW | B6: Earning | C6: LAPTOP_ALLOW | D6: 3713 | E6: Regular Remuneration | F6: 100 | G6: 1 | H6: 1 | I6: 1 | J6: Taxable allowance
A7: SOFT_ALLOW | B7: Earning | C7: SOFT_ALL / SOFT_ALLOW | D7: 3713 | E7: Regular Remuneration | F7: 100 | G7: 1 | H7: 1 | I7: 1 | J7: Source uses two spellings; one component
A8: LIFE_COVER | B8: Earning | C8: LIFE_COVER (earning) | D8: 3801 | E8: Regular Remuneration | F8: 100 | G8: 1 | H8: 1 | I8: 1 | J8: Taxable fringe, recovered by LIFE_COVER_DED
A9: HBR | B9: Earning | C9: HBR | D9: 3601 | E9: Regular Remuneration | F9: 100 | G9: 1 | H9: 1 | I9: 1 | J9: Hours x rate; hours footer not modelled
A10: PS_RISK | B10: Earning | C10: PS_RISK | D10: 3606 | E10: Commission | F10: 100 | G10: 1 | H10: 1 | I10: 1 | J10: Hours x rate
A11: GS_VARIABLE | B11: Earning | C11: GS_VARIABLE | D11: 3606 | E11: Commission | F11: 100 | G11: 1 | H11: 1 | I11: 1 | J11: Variable pay
A12: BONUS | B12: Earning | C12: BONUS | D12: 3605 | E12: Annual Payment (once-off full tax) | F12: 100 | G12: 1 | H12: 1 | I12: 1 | J12: Source taxes bonus as annual payment
A13: REFERAL | B13: Earning | C13: REFERAL | D13: 3605 | E13: Regular Remuneration | F13: 100 | G13: 1 | H13: 1 | I13: 1 | J13: No evidence either way in sample
A14: COMM_REIMBURSE | B14: Earning | C14: COMM_REIMBURSE | D14: 3714 | E14: Non-Taxable Reimbursement | F14: 0 | G14: 0 | H14: 0 | I14: 0 | J14: Excluded from PAYE, UIF, SDL, IRP5
A15: EXPCLAIM | B15: Earning | C15: EXPCLAIM | D15: 3714 | E15: Non-Taxable Reimbursement | F15: 0 | G15: 0 | H15: 0 | I15: 0 | J15: Excluded from PAYE, UIF, SDL, IRP5
A16: LIFE_COVER_DED | B16: Deduction | C16: LIFE_COVER (deduction) | D16: - | E16: Working Paper Only | F16: 0 | G16: 0 | H16: 0 | I16: 0 | J16: Name differs: Frappe component names are unique
... A24: SDL Contribution | B24: Company contribution | C24: SDL | D24: 4142 | E24: SDL | F24: 0 | G24: 0 | H24: 0 | I24: 0 | J24: 1% of leviable amount
A26: Salary Structure: MET GS Consultant Monthly (SALARY=base; PAYE; company contributions UIF employer + SDL). All other pay items arrive through 206 submitted Additional Salary records (recurring where the amount repeats).
A27: Salary Structure Assignments: 23, split at 1 Oct 2025, 1 Mar 2026 (new Income Tax Slab) and at mid-year salary changes (employee 010: 1 Jun 2026).
A28: Income Tax Slabs: South Africa 2025-2026 - MET and South Africa 2026-2027 - MET (pre-existing). Rebates R17 235 / R17 820; medical credit R364 / R376 per month (employee 006).
A29: Take-on: BMA Payroll Take-On 'year-to-date totals' for 1 Mar - 30 Sep 2025 (7 periods), prepared by Payroll Admin (test), submitted by Payroll Manager (test) - maker-checker honoured.
A30: Payroll: 12 Payroll Entries (Oct 2025 - Sep 2026), 132 submitted Salary Slips, 24 accrual journals. EMP201 x12, interim EMP501 (Mar - Aug 2026) with 11 submitted IRP5 certificates.
A31: Payroll Settings: Allow Packaged Statutory Rates = ticked (practitioner sign-off required; no approved ZA Statutory Rate Pack exists).

Sheet Derived Opening Balances
A1: Take-on opening balances for 1 Mar - 30 Sep 2025 (derived, not source data)
A2: The sample starts in Oct 2025. Opening taxable income and PAYE were solved so Oct 2025 matches, then Nov-Feb were used as independent checks.
A4: Employee | B4: Taxable income to 30 Sep 2025 | C4: PAYE paid to 30 Sep 2025 | D4: Periods represented
A5: Thabo Mokoena - 001 | B5: 635382 | C5: 191838.92 | D5: 7
A6: Lerato Dlamini - 002 | B6: 934599 | C6: 314517.9 | D6: 7
A7: Pieter van der Merwe - 003 | B7: 301328 | C7: 61487.01 | D7: 7
A8: Naledi Khumalo - 004 | B8: 1176075 | C8: 418169.38 | D8: 7
A9: Sipho Ndlovu - 005 | B9: 391982 | C9: 94232.17 | D9: 7
A10: Annelie Botha - 006 | B10: 1090632 | C10: 377172.03 | D10: 7
A11: Kagiso Molefe - 007 | B11: 318782 | C11: 67880.17 | D11: 7
A12: Ayesha Patel - 008 | B12: 290622 | C12: 58168.15 | D12: 7
A13: Johan Pretorius - 009 | B13: 497725 | C13: 135453.9 | D13: 7
A14: Zanele Nkosi - 010 | B14: 316664 | C14: 67117.7 | D14: 7
A15: Michael O'Connor - 011 | B15: 654667 | C15: 199745.79 | D15: 7
